
saving a checkpoint for step 1
Traceback (most recent call last):
  File "/home/jha0007/mesh-transformer/device_train.py", line 58, in save
    with open(f"gs://{bucket}/{path}/meta.json", "r") as f:
  File "/home/jha0007/miniconda3/envs/ml_exp/lib/python3.9/site-packages/smart_open/smart_open_lib.py", line 235, in open
    binary = _open_binary_stream(uri, binary_mode, transport_params)
  File "/home/jha0007/miniconda3/envs/ml_exp/lib/python3.9/site-packages/smart_open/smart_open_lib.py", line 398, in _open_binary_stream
    fobj = submodule.open_uri(uri, mode, transport_params)
  File "/home/jha0007/miniconda3/envs/ml_exp/lib/python3.9/site-packages/smart_open/gcs.py", line 105, in open_uri
    return open(parsed_uri['bucket_id'], parsed_uri['blob_id'], mode, **kwargs)
  File "/home/jha0007/miniconda3/envs/ml_exp/lib/python3.9/site-packages/smart_open/gcs.py", line 138, in open
    fileobj = Reader(
  File "/home/jha0007/miniconda3/envs/ml_exp/lib/python3.9/site-packages/smart_open/gcs.py", line 224, in __init__
    raise google.cloud.exceptions.NotFound('blob %s not found in %s' % (key, bucket))
google.api_core.exceptions.NotFound: 404 blob mesh_jax_pile_6B_rotary/meta.json not found in gpt-j-trainer-sql
During handling of the above exception, another exception occurred:
Traceback (most recent call last):
  File "/home/jha0007/miniconda3/envs/ml_exp/lib/python3.9/site-packages/google/cloud/storage/blob.py", line 2713, in create_resumable_upload_session
    upload, _ = self._initiate_resumable_upload(
  File "/home/jha0007/miniconda3/envs/ml_exp/lib/python3.9/site-packages/google/cloud/storage/blob.py", line 1916, in _initiate_resumable_upload
    upload.initiate(
  File "/home/jha0007/miniconda3/envs/ml_exp/lib/python3.9/site-packages/google/resumable_media/requests/upload.py", line 413, in initiate
    self._process_initiate_response(response)
  File "/home/jha0007/miniconda3/envs/ml_exp/lib/python3.9/site-packages/google/resumable_media/_upload.py", line 502, in _process_initiate_response
    _helpers.require_status_code(
  File "/home/jha0007/miniconda3/envs/ml_exp/lib/python3.9/site-packages/google/resumable_media/_helpers.py", line 99, in require_status_code
    raise common.InvalidResponse(
google.resumable_media.common.InvalidResponse: ('Request failed with status code', 403, 'Expected one of', <HTTPStatus.OK: 200>, <HTTPStatus.CREATED: 201>)
During handling of the above exception, another exception occurred:
Traceback (most recent call last):
  File "/home/jha0007/mesh-transformer/device_train.py", line 302, in <module>
    save(network, step, bucket, model_dir,
  File "/home/jha0007/mesh-transformer/device_train.py", line 62, in save
    with open(f"gs://{bucket}/{path}/meta.json", "w") as f:
  File "/home/jha0007/miniconda3/envs/ml_exp/lib/python3.9/site-packages/smart_open/smart_open_lib.py", line 235, in open
    binary = _open_binary_stream(uri, binary_mode, transport_params)
  File "/home/jha0007/miniconda3/envs/ml_exp/lib/python3.9/site-packages/smart_open/smart_open_lib.py", line 398, in _open_binary_stream
    fobj = submodule.open_uri(uri, mode, transport_params)
  File "/home/jha0007/miniconda3/envs/ml_exp/lib/python3.9/site-packages/smart_open/gcs.py", line 105, in open_uri
    return open(parsed_uri['bucket_id'], parsed_uri['blob_id'], mode, **kwargs)
  File "/home/jha0007/miniconda3/envs/ml_exp/lib/python3.9/site-packages/smart_open/gcs.py", line 146, in open
    fileobj = Writer(
  File "/home/jha0007/miniconda3/envs/ml_exp/lib/python3.9/site-packages/smart_open/gcs.py", line 427, in __init__
    self._resumable_upload_url = self._blob.create_resumable_upload_session()
  File "/home/jha0007/miniconda3/envs/ml_exp/lib/python3.9/site-packages/google/cloud/storage/blob.py", line 2728, in create_resumable_upload_session
    _raise_from_invalid_response(exc)
  File "/home/jha0007/miniconda3/envs/ml_exp/lib/python3.9/site-packages/google/cloud/storage/blob.py", line 3936, in _raise_from_invalid_response
    raise exceptions.from_http_status(response.status_code, message, response=response)
google.api_core.exceptions.Forbidden: 403 POST https://storage.googleapis.com/upload/storage/v1/b/gpt-j-trainer-sql/o?uploadType=resumable: {
  "error": {
    "code": 403,
    "message": "Access denied.",
    "errors": [
      {
        "message": "Access denied.",
        "domain": "global",
        "reason": "forbidden"
      }
    ]
  }
}
: ('Request failed with status code', 403, 'Expected one of', <HTTPStatus.OK: 200>, <HTTPStatus.CREATED: 201>)
Traceback (most recent call last):
  File "/home/jha0007/mesh-transformer/device_train.py", line 58, in save
    with open(f"gs://{bucket}/{path}/meta.json", "r") as f:
  File "/home/jha0007/miniconda3/envs/ml_exp/lib/python3.9/site-packages/smart_open/smart_open_lib.py", line 235, in open
    binary = _open_binary_stream(uri, binary_mode, transport_params)
  File "/home/jha0007/miniconda3/envs/ml_exp/lib/python3.9/site-packages/smart_open/smart_open_lib.py", line 398, in _open_binary_stream
    fobj = submodule.open_uri(uri, mode, transport_params)
  File "/home/jha0007/miniconda3/envs/ml_exp/lib/python3.9/site-packages/smart_open/gcs.py", line 105, in open_uri
    return open(parsed_uri['bucket_id'], parsed_uri['blob_id'], mode, **kwargs)
  File "/home/jha0007/miniconda3/envs/ml_exp/lib/python3.9/site-packages/smart_open/gcs.py", line 138, in open
    fileobj = Reader(
  File "/home/jha0007/miniconda3/envs/ml_exp/lib/python3.9/site-packages/smart_open/gcs.py", line 224, in __init__
    raise google.cloud.exceptions.NotFound('blob %s not found in %s' % (key, bucket))
google.api_core.exceptions.NotFound: 404 blob mesh_jax_pile_6B_rotary/meta.json not found in gpt-j-trainer-sql
During handling of the above exception, another exception occurred:
Traceback (most recent call last):
  File "/home/jha0007/miniconda3/envs/ml_exp/lib/python3.9/site-packages/google/cloud/storage/blob.py", line 2713, in create_resumable_upload_session
    upload, _ = self._initiate_resumable_upload(
  File "/home/jha0007/miniconda3/envs/ml_exp/lib/python3.9/site-packages/google/cloud/storage/blob.py", line 1916, in _initiate_resumable_upload
    upload.initiate(
  File "/home/jha0007/miniconda3/envs/ml_exp/lib/python3.9/site-packages/google/resumable_media/requests/upload.py", line 413, in initiate
    self._process_initiate_response(response)
  File "/home/jha0007/miniconda3/envs/ml_exp/lib/python3.9/site-packages/google/resumable_media/_upload.py", line 502, in _process_initiate_response
    _helpers.require_status_code(
  File "/home/jha0007/miniconda3/envs/ml_exp/lib/python3.9/site-packages/google/resumable_media/_helpers.py", line 99, in require_status_code
    raise common.InvalidResponse(
google.resumable_media.common.InvalidResponse: ('Request failed with status code', 403, 'Expected one of', <HTTPStatus.OK: 200>, <HTTPStatus.CREATED: 201>)
During handling of the above exception, another exception occurred:
Traceback (most recent call last):
  File "/home/jha0007/mesh-transformer/device_train.py", line 302, in <module>
    save(network, step, bucket, model_dir,
  File "/home/jha0007/mesh-transformer/device_train.py", line 62, in save
    with open(f"gs://{bucket}/{path}/meta.json", "w") as f:
  File "/home/jha0007/miniconda3/envs/ml_exp/lib/python3.9/site-packages/smart_open/smart_open_lib.py", line 235, in open
    binary = _open_binary_stream(uri, binary_mode, transport_params)
  File "/home/jha0007/miniconda3/envs/ml_exp/lib/python3.9/site-packages/smart_open/smart_open_lib.py", line 398, in _open_binary_stream
    fobj = submodule.open_uri(uri, mode, transport_params)
  File "/home/jha0007/miniconda3/envs/ml_exp/lib/python3.9/site-packages/smart_open/gcs.py", line 105, in open_uri
    return open(parsed_uri['bucket_id'], parsed_uri['blob_id'], mode, **kwargs)
  File "/home/jha0007/miniconda3/envs/ml_exp/lib/python3.9/site-packages/smart_open/gcs.py", line 146, in open
    fileobj = Writer(
  File "/home/jha0007/miniconda3/envs/ml_exp/lib/python3.9/site-packages/smart_open/gcs.py", line 427, in __init__
    self._resumable_upload_url = self._blob.create_resumable_upload_session()
  File "/home/jha0007/miniconda3/envs/ml_exp/lib/python3.9/site-packages/google/cloud/storage/blob.py", line 2728, in create_resumable_upload_session
    _raise_from_invalid_response(exc)
  File "/home/jha0007/miniconda3/envs/ml_exp/lib/python3.9/site-packages/google/cloud/storage/blob.py", line 3936, in _raise_from_invalid_response
    raise exceptions.from_http_status(response.status_code, message, response=response)
google.api_core.exceptions.Forbidden: 403 POST https://storage.googleapis.com/upload/storage/v1/b/gpt-j-trainer-sql/o?uploadType=resumable: {
  "error": {
    "code": 403,
    "message": "Access denied.",
    "errors": [
      {
        "message": "Access denied.",
        "domain": "global",
        "reason": "forbidden"
      }
    ]
  }
}
: ('Request failed with status code', 403, 'Expected one of', <HTTPStatus.OK: 200>, <HTTPStatus.CREATED: 201>)